<mujoco model="one_dof_prismatic">
  <compiler angle="radian"/>
  <option timestep="0.002" integrator="RK4" gravity="0 0 0"/>

  <worldbody>
    <body name="link1">
      <inertial pos="0 0 0.5" mass="1" diaginertia="0.01 0.01 0.001"/>
      <joint name="joint1" type="slide" pos="0 0 0" axis="0 0 1" range="-1 1" limited="true"/>
      <geom size="0.05 0.05 0.5" pos="0 0 0.5" type="box" rgba="0.7 0.7 0.7 1"/>
    </body>
  </worldbody>

  
  <actuator>
    <general name="joint1" joint="joint1" ctrlrange="-1 1"/>
  </actuator>

</mujoco>
